Workbook

Sheet ヒアリングシート
B1: Web 制作 事前ヒアリングシート
B5: 契約前の事前ヒアリング ★ = 必須項目
B7: ① 基本情報
B8: ★ 会社名 / 個人名 | C8: 例）株式会社〇〇 / 山田 太郎
B9: 担当者名 | C9: 例）田中 花子
B10: メールアドレス | C10: 例）info@example.com
B11: 電話番号 | C11: 例）03-1234-5678
B12: ヒアリング実施日 | E12: ★ 希望納期
B13: ★ ご予算（目安） | C13: 例）30〜50万円 / 月額20万円 など
B14: ★ 依頼の目的・ゴール | C14: 例）問い合わせ件数を増やしたい / 採用強化 / ブランド認知向上
B16: ② 優先度・重視ポイント（1つ選択）
B17: 最も重視するポイント | C17: クオリティー | E17: 制作提案時の重視点として使用します
B19: ③ 素材・テキスト準備状況
B20: テキスト原稿の準備 | C20: なし | E20: 写真・ロゴ等の素材 | F20: なし（用意が必要）
B22: ④ 制作依頼内容
B23: ★ 制作範囲 | C23: 新規制作 | E23: 依頼内容（複数可） | F23: デザイン＋コーディング
B24: ★ LPの内容・ページ概要 | C24: 例）美容クリニックの糸リフトLP
B26: 機能実装の希望 | C26: 未定 | E26: ★ 想定するCMS | F26: WordPress
B27: 希望する機能の詳細 | C27: 例）会員登録、予約、決済、会員別表示など
B28: フォーム実装 | C28: 未定
B29: 参考サイト（任意） | C29: 例）https://example.com/
B31: ⑤ デザイン希望
B32: デザインスタイル | C32: 未定 | E32: アニメーション | F32: お任せ
B33: クオリティーレベル | C33: NORMAL
B35: ⑥ 公開後・運用体制
B36: ★ 公開後の運用体制 | C36: 未定 | E36: アフターサポート希望 | F36: 例）月次レポート、セキュリティ更新、トラブル対応
B38: ⑦ 技術・環境関連
B39: ★ ドメイン・サーバー | C39: 不明 | E39: ★ SEO対策の希望 | F39: 最低限でよい
B40: SNS連携 | C40: Instagram
B42: ⑧ 備考・その他ご要望
B43: その他ご要望・補足 | C43: 自由にご記入ください
B48: ◆ 入力チェック（必須項目）
B49: =COUNTA(C8,F12,C13,C14,C23,F26,C36,C39,F39) | D49: / 9 項目入力済み | E49: =IFS(COUNTA(C8,F12,C13,C14,C23,F26,C36,C39,F39)=9,"✔ 入力完了 — 送付可能",COUNTA(C8,F12,C13,C14,C23,F26,C36,C39,F39)>=5,"⚠ 入力中 — 残り項目あり",TRUE,"✗ 未入力項目が多数あります")
B51: =IF(IFERROR(LEN(C8)>0,FALSE),"✔","✗") | C51: 会社名 / 個人名
B52: =IF(IFERROR(LEN(F12)>0,FALSE),"✔","✗") | C52: 希望納期
B53: =IF(IFERROR(LEN(C13)>0,FALSE),"✔","✗") | C53: ご予算
B54: =IF(IFERROR(LEN(C14)>0,FALSE),"✔","✗") | C54: 依頼の目的・ゴール
B55: =IF(IFERROR(LEN(C23)>0,FALSE),"✔","✗") | C55: 制作範囲
B56: =IF(IFERROR(LEN(F26)>0,FALSE),"✔","✗") | C56: 想定するCMS
B57: =IF(IFERROR(LEN(C36)>0,FALSE),"✔","✗") | C57: 公開後の運用体制
...

Sheet 案件サマリー
B1: 案件サマリー ／ 自動集計シート
B5: ヒアリングシートの入力内容を自動で集計・表示します（編集不要）
B7: 基本情報
B8: 会社名 / 個人名 | C8: =IFERROR('ヒアリングシート'!C8,"")
B9: 担当者名 | C9: =IFERROR('ヒアリングシート'!C9,"")
B10: メールアドレス | C10: =IFERROR('ヒアリングシート'!C10,"")
B11: 電話番号 | C11: =IFERROR('ヒアリングシート'!C11,"")
B12: ヒアリング実施日 | C12: =IFERROR(TEXT('ヒアリングシート'!C12,"YYYY/MM/DD"),"")
B13: 希望納期 | C13: =IFERROR(TEXT('ヒアリングシート'!F12,"YYYY/MM/DD"),"")
B14: ご予算（目安） | C14: =IFERROR('ヒアリングシート'!C13,"")
B15: 依頼の目的・ゴール | C15: =IFERROR('ヒアリングシート'!C14,"")
B17: 制作依頼内容
B18: 重視ポイント | C18: =IFERROR('ヒアリングシート'!C17,"")
B19: 制作範囲 | C19: =IFERROR('ヒアリングシート'!C23,"")
B20: 依頼内容 | C20: =IFERROR('ヒアリングシート'!F23,"")
B21: LPの内容・概要 | C21: =IFERROR('ヒアリングシート'!C24,"")
B22: 機能実装 | C22: =IFERROR('ヒアリングシート'!C26,"")
B23: 希望する機能の詳細 | C23: =IFERROR('ヒアリングシート'!C27,"")
B24: フォーム実装 | C24: =IFERROR('ヒアリングシート'!C28,"")
B25: 想定するCMS | C25: =IFERROR('ヒアリングシート'!F26,"")
B26: 参考サイト | C26: =IFERROR('ヒアリングシート'!C29,"")
B28: デザイン・技術環境
B29: デザインスタイル | C29: =IFERROR('ヒアリングシート'!C32,"")
B30: アニメーション | C30: =IFERROR('ヒアリングシート'!F32,"")
B31: クオリティーレベル | C31: =IFERROR('ヒアリングシート'!C33,"")
B32: 公開後の運用 | C32: =IFERROR('ヒアリングシート'!C36,"")
B33: アフターサポート | C33: =IFERROR('ヒアリングシート'!F36,"")
B34: ドメイン・サーバー | C34: =IFERROR('ヒアリングシート'!C39,"")
B35: SEO対策 | C35: =IFERROR('ヒアリングシート'!F39,"")
B36: SNS連携 | C36: =IFERROR('ヒアリングシート'!C40,"")
B38: 素材・準備状況
B39: テキスト原稿 | C39: =IFERROR('ヒアリングシート'!C20,"")
B40: 写真・ロゴ等の素材 | C40: =IFERROR('ヒアリングシート'!F20,"")
B42: 備考・その他ご要望
B43: その他ご要望・補足 | C43: =IFERROR('ヒアリングシート'!C43,"")
B45: 入力ステータス
B46: =IFERROR('ヒアリングシート'!E49,"")

Sheet マスターデータ
B1: マスターデータ ／ 選択肢・定義一覧
B5: 各項目の選択肢と定義を管理するシートです（必要に応じて編集可）
B7: 優先度（重視ポイント） | E7: アニメーション
B8: クオリティー | C8: 仕上がりの質・完成度を最優先 | E8: ダイナミックアニメーション（かなり動きます） | F8: スクロールアニメーション等を多用
B9: コスト | C9: 予算内での最大効果を優先 | E9: 少なめ | F9: 控えめなアニメーション
B10: 速さ | C10: 納期・スピードを最優先 | E10: お任せ | F10: 制作者に一任
B11: 機能性 | C11: 機能・操作性を最優先 | E11: 無し | F11: アニメーションなし
B13: 制作範囲 | E13: クオリティーレベル
B14: 新規制作 | C14: ゼロから新しく制作 | E14: ハイクオリティー（ダイナミックアニメーションや機能性LP） | F14: 最高品質・高度な実装
B15: リニューアル | C15: 既存サイトを全面刷新 | E15: NORMAL | F15: 標準的な品質
B16: 一部修正 | C16: 既存サイトの一部を変更 | E16: 画像ベース | F16: 画像中心のシンプルな実装
B18: 想定CMS | E18: 公開後の運用
B19: WordPress | C19: 世界シェアNo.1のCMS | E19: 自社で更新したい | F19: クライアントが自社で更新
B20: Shopify | C20: ECに特化したプラットフォーム | E20: 運用も依頼したい | F20: 制作会社に運用を委託
B21: MakeShop | C21: 国産ECプラットフォーム | E21: 未定 | F21: 運用方針が未決定
B22: Wix | C22: ノーコードWebサイトビルダー
B23: STUDIO | C23: 国産ノーコードデザインツール | E23: ドメイン・サーバー
B24: 不明 | C24: CMSが未決定・不明 | E24: 取得・契約済み | F24: 既にドメイン・サーバーを保有
B25: その他 | C25: 上記以外のCMS | E25: 未取得（依頼希望） | F25: 取得・契約を制作会社に依頼
E26: 不明 | F26: 状況が不明
B27: デザインスタイル
B28: シンプル | C28: 余白を活かしたミニマルデザイン | E28: SNS連携
B29: 高級感 | C29: 上質・プレミアム感のあるデザイン | E29: Instagram | F29: Instagramフィード・リンク連携
B30: ポップ | C30: カラフルで明るいデザイン | E30: X（旧Twitter） | F30: Xフィード・リンク連携
B31: ナチュラル | C31: 温かみのある自然系デザイン | E31: Facebook | F31: Facebookページ連携
B32: クール | C32: スタイリッシュでモダンなデザイン | E32: LINE | F32: LINE公式アカウント連携
B33: 未定 | C33: デザイン方向性が未決定 | E33: Instagram＋X | F33: Instagram＋X両方
E34: Instagram＋LINE | F34: Instagram＋LINE両方
B35: SEO対策 | E35: その他 | F35: 上記以外のSNS
B36: 強く希望する | C36: SEO施策を積極的に実施 | E36: 不要 | F36: SNS連携なし
B37: 最低限でよい | C37: 基本的なSEO設定のみ
B38: 不要 | C38: SEO対策は不要
